<?xml version="1.0"?>
<robot xmlns:xacro="http://www.ros.org/wiki/xacro" >

    <xacro:include filename="inertial_macros.xacro"/>

    <material name="white">
        <color rgba="1 1 1 1"/>
    </material>

    <material name="orange">
        <color rgba="1 0.3 0.1 1"/>
    </material>

    <material name="yellow">
        <color rgba="1 1 0.1 1"/>
    </material>

    <material name="blue">
            <color rgba="0.2 0.2 1 1"/>
    </material>

    <material name="black">
            <color rgba="0.1 0.1 0.1 1"/>
    </material>

<!--BASE LINK-->

    <link name="base_link">

    </link>

<!--CHASSI LINK-->

    <joint name="chassis_joint" type="fixed">
        <parent link="base_link"/>
        <child link="chassis"/>
        <origin xyz="-0.045 0 0"/>
    </joint>

    <link name="chassis">
        <visual>
            <origin xyz="0.10 0 0.075"/>      
            <geometry>
                <box size="0.2 0.2 0.15"/>
            </geometry>   
            <material name="black"/>
        </visual>

            <collision>
                <origin xyz="0.10 0 0.075"/>      
                <geometry>
                    <box size="0.2 0.2 0.15"/>
                </geometry>   
            </collision>
            <xacro:inertial_box mass="0.5" x="0.2" y="0.2" z="0.15">
                <origin xyz="0.10 0 0.075" rpy="0 0 0"/>
            </xacro:inertial_box>
    </link>

<!--LEFT WHEEL LINK--> 

<joint name="left_wheel_joint" type="continuous">
    <parent link="base_link"/>
    <child link="left_wheel"/>
    <origin xyz="0 0.115 -0.015" rpy="-${pi/2} 0 0"/>
    <axis xyz="0 0 1"/>
</joint>

<link name="left_wheel">
    <visual>
        <geometry>
            <cylinder radius="0.0325" length="0.025"/>
        </geometry>
        <material name="yellow"/>
    </visual>

        <collision>
            <geometry>
                <cylinder radius="0.0325" length="0.025"/>
            </geometry>
        </collision>

            <xacro:inertial_cylinder mass="0.1" length="0.025" radius="0.0325" >
                    <origin xyz="0 0 0" rpy="0 0 0"/>
            </xacro:inertial_cylinder>
</link>

<!--RIGTH WHEEL LINK--> 

<joint name="rigth_wheel_joint" type="continuous">
    <parent link="base_link"/>
    <child link="rigth_wheel"/>
    <origin xyz="0 -0.115 -0.015" rpy="${pi/2} 0 0"/>
    <axis xyz="0 0 -1"/>
</joint>

<link name="rigth_wheel">
    <visual>
        <geometry>
            <cylinder radius="0.0325" length="0.025"/>
        </geometry>
        <material name="yellow"/>
    </visual>

        <collision>
            <geometry>
                <cylinder radius="0.0325" length="0.025"/>
            </geometry>
        </collision>

            <xacro:inertial_cylinder mass="0.1" length="0.025" radius="0.0325" >
                    <origin xyz="0 0 0" rpy="0 0 0"/>
            </xacro:inertial_cylinder>
</link>

<!--CASTER WHEEL LINK-->

<joint name="caster_wheel_joint" type="fixed">
    <origin xyz="0.185 0.0 -0.015" />
    <parent link="chassis"/>
    <child link="caster_wheel"/>
</joint>

<link name="caster_wheel">
    <visual>
        <geometry>
            <sphere radius="0.0325"/> 
        </geometry>
        <material name="orange"/>
    </visual> 

        <collision>
            <geometry>
                <sphere radius="0.0325"/> 
            </geometry>
        </collision> 

            <xacro:inertial_sphere mass="0.1"  radius="0.0325" >
                    <origin xyz="0 0 0" rpy="0 0 0"/>
            </xacro:inertial_sphere>
        
</link>

</robot>

